Workbook

Sheet LLM
A2: Enter flag:
A3: Result: | B3: =IF(VERIFY!Z1=1,"✅ Correct","❌ Incorrect") -> #NAME?

Sheet BITS
B2: =MOD(com.sun.star.sheet.addin.Analysis.getQuotient(IFERROR(CODE(MID(LLM!B2,1,1)),0),2^7),2) -> #NAME?
B3: =MOD(com.sun.star.sheet.addin.Analysis.getQuotient(IFERROR(CODE(MID(LLM!B2,1,1)),0),2^6),2) -> #NAME?
B4: =MOD(com.sun.star.sheet.addin.Analysis.getQuotient(IFERROR(CODE(MID(LLM!B2,1,1)),0),2^5),2) -> #NAME?
B5: =MOD(com.sun.star.sheet.addin.Analysis.getQuotient(IFERROR(CODE(MID(LLM!B2,1,1)),0),2^4),2) -> #NAME?
B6: =MOD(com.sun.star.sheet.addin.Analysis.getQuotient(IFERROR(CODE(MID(LLM!B2,1,1)),0),2^3),2) -> #NAME?
B7: =MOD(com.sun.star.sheet.addin.Analysis.getQuotient(IFERROR(CODE(MID(LLM!B2,1,1)),0),2^2),2) -> #NAME?
B8: =MOD(com.sun.star.sheet.addin.Analysis.getQuotient(IFERROR(CODE(MID(LLM!B2,1,1)),0),2^1),2) -> #NAME?
B9: =MOD(com.sun.star.sheet.addin.Analysis.getQuotient(IFERROR(CODE(MID(LLM!B2,1,1)),0),2^0),2) -> #NAME?
B10: =MOD(com.sun.star.sheet.addin.Analysis.getQuotient(IFERROR(CODE(MID(LLM!B2,2,1)),0),2^7),2) -> #NAME?
B11: =MOD(com.sun.star.sheet.addin.Analysis.getQuotient(IFERROR(CODE(MID(LLM!B2,2,1)),0),2^6),2) -> #NAME?
B12: =MOD(com.sun.star.sheet.addin.Analysis.getQuotient(IFERROR(CODE(MID(LLM!B2,2,1)),0),2^5),2) -> #NAME?
B13: =MOD(com.sun.star.sheet.addin.Analysis.getQuotient(IFERROR(CODE(MID(LLM!B2,2,1)),0),2^4),2) -> #NAME?
B14: =MOD(com.sun.star.sheet.addin.Analysis.getQuotient(IFERROR(CODE(MID(LLM!B2,2,1)),0),2^3),2) -> #NAME?
B15: =MOD(com.sun.star.sheet.addin.Analysis.getQuotient(IFERROR(CODE(MID(LLM!B2,2,1)),0),2^2),2) -> #NAME?
B16: =MOD(com.sun.star.sheet.addin.Analysis.getQuotient(IFERROR(CODE(MID(LLM!B2,2,1)),0),2^1),2) -> #NAME?
B17: =MOD(com.sun.star.sheet.addin.Analysis.getQuotient(IFERROR(CODE(MID(LLM!B2,2,1)),0),2^0),2) -> #NAME?
B18: =MOD(com.sun.star.sheet.addin.Analysis.getQuotient(IFERROR(CODE(MID(LLM!B2,3,1)),0),2^7),2) -> #NAME?
B19: =MOD(com.sun.star.sheet.addin.Analysis.getQuotient(IFERROR(CODE(MID(LLM!B2,3,1)),0),2^6),2) -> #NAME?
B20: =MOD(com.sun.star.sheet.addin.Analysis.getQuotient(IFERROR(CODE(MID(LLM!B2,3,1)),0),2^5),2) -> #NAME?
B21: =MOD(com.sun.star.sheet.addin.Analysis.getQuotient(IFERROR(CODE(MID(LLM!B2,3,1)),0),2^4),2) -> #NAME?
B22: =MOD(com.sun.star.sheet.addin.Analysis.getQuotient(IFERROR(CODE(MID(LLM!B2,3,1)),0),2^3),2) -> #NAME?
B23: =MOD(com.sun.star.sheet.addin.Analysis.getQuotient(IFERROR(CODE(MID(LLM!B2,3,1)),0),2^2),2) -> #NAME?
B24: =MOD(com.sun.star.sheet.addin.Analysis.getQuotient(IFERROR(CODE(MID(LLM!B2,3,1)),0),2^1),2) -> #NAME?
B25: =MOD(com.sun.star.sheet.addin.Analysis.getQuotient(IFERROR(CODE(MID(LLM!B2,3,1)),0),2^0),2) -> #NAME?
B26: =MOD(com.sun.star.sheet.addin.Analysis.getQuotient(IFERROR(CODE(MID(LLM!B2,4,1)),0),2^7),2) -> #NAME?
B27: =MOD(com.sun.star.sheet.addin.Analysis.getQuotient(IFERROR(CODE(MID(LLM!B2,4,1)),0),2^6),2) -> #NAME?
B28: =MOD(com.sun.star.sheet.addin.Analysis.getQuotient(IFERROR(CODE(MID(LLM!B2,4,1)),0),2^5),2) -> #NAME?
B29: =MOD(com.sun.star.sheet.addin.Analysis.getQuotient(IFERROR(CODE(MID(LLM!B2,4,1)),0),2^4),2) -> #NAME?
B30: =MOD(com.sun.star.sheet.addin.Analysis.getQuotient(IFERROR(CODE(MID(LLM!B2,4,1)),0),2^3),2) -> #NAME?
B31: =MOD(com.sun.star.sheet.addin.Analysis.getQuotient(IFERROR(CODE(MID(LLM!B2,4,1)),0),2^2),2) -> #NAME?
B32: =MOD(com.sun.star.sheet.addin.Analysis.getQuotient(IFERROR(CODE(MID(LLM!B2,4,1)),0),2^1),2) -> #NAME?
B33: =MOD(com.sun.star.sheet.addin.Analysis.getQuotient(IFERROR(CODE(MID(LLM!B2,4,1)),0),2^0),2) -> #NAME?
B34: =MOD(com.sun.star.sheet.addin.Analysis.getQuotient(IFERROR(CODE(MID(LLM!B2,5,1)),0),2^7),2) -> #NAME?
B35: =MOD(com.sun.star.sheet.addin.Analysis.getQuotient(IFERROR(CODE(MID(LLM!B2,5,1)),0),2^6),2) -> #NAME?
B36: =MOD(com.sun.star.sheet.addin.Analysis.getQuotient(IFERROR(CODE(MID(LLM!B2,5,1)),0),2^5),2) -> #NAME?
B37: =MOD(com.sun.star.sheet.addin.Analysis.getQuotient(IFERROR(CODE(MID(LLM!B2,5,1)),0),2^4),2) -> #NAME?
B38: =MOD(com.sun.star.sheet.addin.Analysis.getQuotient(IFERROR(CODE(MID(LLM!B2,5,1)),0),2^3),2) -> #NAME?
B39: =MOD(com.sun.star.sheet.addin.Analysis.getQuotient(IFERROR(CODE(MID(LLM!B2,5,1)),0),2^2),2) -> #NAME?
B40: =MOD(com.sun.star.sheet.addin.Analysis.getQuotient(IFERROR(CODE(MID(LLM!B2,5,1)),0),2^1),2) -> #NAME?
B41: =MOD(com.sun.star.sheet.addin.Analysis.getQuotient(IFERROR(CODE(MID(LLM!B2,5,1)),0),2^0),2) -> #NAME?
...

Sheet WEIGHTS
A2: -15 | B2: 55 | C2: 28 | D2: 12 | E2: -42 | F2: -42 | G2: -54 | H2: 45
A3: 12 | B3: -351 | C3: -73 | D3: 97 | E3: 280 | F3: -54 | G3: -209 | H3: -39
A4: -24 | B4: -335 | C4: -54 | D4: 137 | E4: 262 | F4: -60 | G4: -165 | H4: 1
A5: -5 | B5: -287 | C5: -49 | D5: 249 | E5: 334 | F5: -391 | G5: -161 | H5: -40
A6: -53 | B6: -305 | C6: 6 | D6: -47 | E6: -710 | F6: 401 | G6: 364 | H6: -7
A7: -46 | B7: -263 | C7: -62 | D7: -64 | E7: -606 | F7: 734 | G7: 180 | H7: 16
A8: 6 | B8: -244 | C8: 7 | D8: 158 | E8: 430 | F8: 181 | G8: -187 | H8: 69
A9: -50 | B9: -234 | C9: -60 | D9: 222 | E9: 455 | F9: -251 | G9: -84 | H9: -18
A10: -27
A11: -527
A12: -99
A13: 217
A14: -384
A15: 577
A16: 94
A17: -19
A18: -81
A19: -493
A20: 3
A21: -1303
... A26: -1060
A28: -15 | B28: 55 | C28: 28 | D28: 12 | E28: -42 | F28: -42 | G28: -54 | H28: 45
A29: 12 | B29: 505 | C29: -79 | D29: 71 | E29: -289 | F29: 127 | G29: -18 | H29: -39
A30: -24 | B30: 535 | C30: -68 | D30: 48 | E30: -226 | F30: 107 | G30: 25 | H30: -3
A31: -5 | B31: 548 | C31: -46 | D31: 147 | E31: -203 | F31: -6 | G31: 62 | H31: -40
A32: -53 | B32: -983 | C32: -6 | D32: -405 | E32: -170 | F32: 831 | G32: 730 | H32: -7
A33: -46 | B33: 773 | C33: -65 | D33: 196 | E33: -147 | F33: -6 | G33: -201 | H33: 17
A34: 6 | B34: -515 | C34: -4 | D34: -365 | E34: -302 | F34: 760 | G34: 424 | H34: 65
A35: -50 | B35: 824 | C35: -63 | D35: 167 | E35: -156 | F35: -112 | G35: 43 | H35: -18
A36: -27
A37: -182
A38: -114
A39: -241
A40: -431
A41: 1162
A42: 596
A43: -23
A44: -81
A45: 616
A46: 0
...

Sheet VERIFY
Z1: =--(SUM(H10,H30,H50,H70,H90,H110,H130,H150,H170,H190,H210,H230,H250,H270,H290,H310,H330,H350,H370,H390,H410,H430,H450,H470,H490,H510,H530)=27) -> #NAME?
C10: =MAX(0,(SUMPRODUCT(BITS!B2:B9,WEIGHTS!A2:A9)+WEIGHTS!A10)/100) -> #NAME? | H10: =--((SUMPRODUCT(C10:C17,WEIGHTS!A18:A25)+WEIGHTS!A26)/100>0) -> #NAME?
C11: =MAX(0,(SUMPRODUCT(BITS!B2:B9,WEIGHTS!B2:B9)+WEIGHTS!A11)/100) -> #NAME?
C12: =MAX(0,(SUMPRODUCT(BITS!B2:B9,WEIGHTS!C2:C9)+WEIGHTS!A12)/100) -> #NAME?
C13: =MAX(0,(SUMPRODUCT(BITS!B2:B9,WEIGHTS!D2:D9)+WEIGHTS!A13)/100) -> #NAME?
C14: =MAX(0,(SUMPRODUCT(BITS!B2:B9,WEIGHTS!E2:E9)+WEIGHTS!A14)/100) -> #NAME?
C15: =MAX(0,(SUMPRODUCT(BITS!B2:B9,WEIGHTS!F2:F9)+WEIGHTS!A15)/100) -> #NAME?
C16: =MAX(0,(SUMPRODUCT(BITS!B2:B9,WEIGHTS!G2:G9)+WEIGHTS!A16)/100) -> #NAME?
C17: =MAX(0,(SUMPRODUCT(BITS!B2:B9,WEIGHTS!H2:H9)+WEIGHTS!A17)/100) -> #NAME?
C30: =MAX(0,(SUMPRODUCT(BITS!B10:B17,WEIGHTS!A28:A35)+WEIGHTS!A36)/100) -> #NAME? | H30: =--((SUMPRODUCT(C30:C37,WEIGHTS!A44:A51)+WEIGHTS!A52)/100>0) -> #NAME?
C31: =MAX(0,(SUMPRODUCT(BITS!B10:B17,WEIGHTS!B28:B35)+WEIGHTS!A37)/100) -> #NAME?
C32: =MAX(0,(SUMPRODUCT(BITS!B10:B17,WEIGHTS!C28:C35)+WEIGHTS!A38)/100) -> #NAME?
C33: =MAX(0,(SUMPRODUCT(BITS!B10:B17,WEIGHTS!D28:D35)+WEIGHTS!A39)/100) -> #NAME?
C34: =MAX(0,(SUMPRODUCT(BITS!B10:B17,WEIGHTS!E28:E35)+WEIGHTS!A40)/100) -> #NAME?
C35: =MAX(0,(SUMPRODUCT(BITS!B10:B17,WEIGHTS!F28:F35)+WEIGHTS!A41)/100) -> #NAME?
C36: =MAX(0,(SUMPRODUCT(BITS!B10:B17,WEIGHTS!G28:G35)+WEIGHTS!A42)/100) -> #NAME?
C37: =MAX(0,(SUMPRODUCT(BITS!B10:B17,WEIGHTS!H28:H35)+WEIGHTS!A43)/100) -> #NAME?
C50: =MAX(0,(SUMPRODUCT(BITS!B18:B25,WEIGHTS!A54:A61)+WEIGHTS!A62)/100) -> #NAME? | H50: =--((SUMPRODUCT(C50:C57,WEIGHTS!A70:A77)+WEIGHTS!A78)/100>0) -> #NAME?
C51: =MAX(0,(SUMPRODUCT(BITS!B18:B25,WEIGHTS!B54:B61)+WEIGHTS!A63)/100) -> #NAME?
C52: =MAX(0,(SUMPRODUCT(BITS!B18:B25,WEIGHTS!C54:C61)+WEIGHTS!A64)/100) -> #NAME?
C53: =MAX(0,(SUMPRODUCT(BITS!B18:B25,WEIGHTS!D54:D61)+WEIGHTS!A65)/100) -> #NAME?
C54: =MAX(0,(SUMPRODUCT(BITS!B18:B25,WEIGHTS!E54:E61)+WEIGHTS!A66)/100) -> #NAME?
C55: =MAX(0,(SUMPRODUCT(BITS!B18:B25,WEIGHTS!F54:F61)+WEIGHTS!A67)/100) -> #NAME?
C56: =MAX(0,(SUMPRODUCT(BITS!B18:B25,WEIGHTS!G54:G61)+WEIGHTS!A68)/100) -> #NAME?
C57: =MAX(0,(SUMPRODUCT(BITS!B18:B25,WEIGHTS!H54:H61)+WEIGHTS!A69)/100) -> #NAME?
C70: =MAX(0,(SUMPRODUCT(BITS!B26:B33,WEIGHTS!A80:A87)+WEIGHTS!A88)/100) -> #NAME? | H70: =--((SUMPRODUCT(C70:C77,WEIGHTS!A96:A103)+WEIGHTS!A104)/100>0) -> #NAME?
C71: =MAX(0,(SUMPRODUCT(BITS!B26:B33,WEIGHTS!B80:B87)+WEIGHTS!A89)/100) -> #NAME?
C72: =MAX(0,(SUMPRODUCT(BITS!B26:B33,WEIGHTS!C80:C87)+WEIGHTS!A90)/100) -> #NAME?
C73: =MAX(0,(SUMPRODUCT(BITS!B26:B33,WEIGHTS!D80:D87)+WEIGHTS!A91)/100) -> #NAME?
C74: =MAX(0,(SUMPRODUCT(BITS!B26:B33,WEIGHTS!E80:E87)+WEIGHTS!A92)/100) -> #NAME?
C75: =MAX(0,(SUMPRODUCT(BITS!B26:B33,WEIGHTS!F80:F87)+WEIGHTS!A93)/100) -> #NAME?
C76: =MAX(0,(SUMPRODUCT(BITS!B26:B33,WEIGHTS!G80:G87)+WEIGHTS!A94)/100) -> #NAME?
C77: =MAX(0,(SUMPRODUCT(BITS!B26:B33,WEIGHTS!H80:H87)+WEIGHTS!A95)/100) -> #NAME?
C90: =MAX(0,(SUMPRODUCT(BITS!B34:B41,WEIGHTS!A106:A113)+WEIGHTS!A114)/100) -> #NAME? | H90: =--((SUMPRODUCT(C90:C97,WEIGHTS!A122:A129)+WEIGHTS!A130)/100>0) -> #NAME?
C91: =MAX(0,(SUMPRODUCT(BITS!B34:B41,WEIGHTS!B106:B113)+WEIGHTS!A115)/100) -> #NAME?
C92: =MAX(0,(SUMPRODUCT(BITS!B34:B41,WEIGHTS!C106:C113)+WEIGHTS!A116)/100) -> #NAME?
C93: =MAX(0,(SUMPRODUCT(BITS!B34:B41,WEIGHTS!D106:D113)+WEIGHTS!A117)/100) -> #NAME?
C94: =MAX(0,(SUMPRODUCT(BITS!B34:B41,WEIGHTS!E106:E113)+WEIGHTS!A118)/100) -> #NAME?
C95: =MAX(0,(SUMPRODUCT(BITS!B34:B41,WEIGHTS!F106:F113)+WEIGHTS!A119)/100) -> #NAME?
C96: =MAX(0,(SUMPRODUCT(BITS!B34:B41,WEIGHTS!G106:G113)+WEIGHTS!A120)/100) -> #NAME?
...
